============================= test session starts ==============================
platform linux -- Python 3.11.0rc1, pytest-8.3.5, pluggy-1.5.0 -- /localdev/ddilbaz/tt-torch/env/venv/bin/python3.11
cachedir: .pytest_cache
rootdir: /localdev/ddilbaz/tt-torch
collecting ... collected 1 item

tests/models/codegen/test_codegen.py::test_codegen[True-eval] Some weights of the model checkpoint at Salesforce/codegen-350M-mono were not used when initializing CodeGenForCausalLM: ['transformer.h.0.attn.causal_mask', 'transformer.h.1.attn.causal_mask', 'transformer.h.10.attn.causal_mask', 'transformer.h.11.attn.causal_mask', 'transformer.h.12.attn.causal_mask', 'transformer.h.13.attn.causal_mask', 'transformer.h.14.attn.causal_mask', 'transformer.h.15.attn.causal_mask', 'transformer.h.16.attn.causal_mask', 'transformer.h.17.attn.causal_mask', 'transformer.h.18.attn.causal_mask', 'transformer.h.19.attn.causal_mask', 'transformer.h.2.attn.causal_mask', 'transformer.h.3.attn.causal_mask', 'transformer.h.4.attn.causal_mask', 'transformer.h.5.attn.causal_mask', 'transformer.h.6.attn.causal_mask', 'transformer.h.7.attn.causal_mask', 'transformer.h.8.attn.causal_mask', 'transformer.h.9.attn.causal_mask']
- This IS expected if you are initializing CodeGenForCausalLM from the checkpoint of a model trained on another task or with another architecture (e.g. initializing a BertForSequenceClassification model from a BertForPreTraining model).
- This IS NOT expected if you are initializing CodeGenForCausalLM from the checkpoint of a model that you expect to be exactly identical (initializing a BertForSequenceClassification model from a BertForSequenceClassification model).
XFAILan
still generate a graph)

============================= 1 xfailed in 23.06s ==============================
